Workbook

Sheet Read me
A1: Batch leftovers to account for — 26 September 2026
A2: Taken from the live O2S on 26 September 2026. Read only: nothing was changed on the live site.
A4: What this is
A5: 57 batches hold 147,374 Kg that is neither packed nor accounted for. 6 of them are closed (24,412 Kg). No batch has ever been reconciled in O2S, so no loss, by-product, divert or rework has been recorded.
A6: What to do (Production Manager — Abdul Majid)
A7: 1. For each batch, fill the 4 yellow columns: Decision, Kg, Loss reason (if loss), Note.
A8: 2. Decision is one of: Stock (real bulk still to pack), Loss, By-product, Divert, Rework. A batch can be split over several rows if needed — copy the row.
A9: 3. Sulfur Coated Urea: the suggestion is By-product to Nitro Sulfur (fines and oversize). Change it if it was loss.
A10: 4. Potassium Humate and other large leftovers are most likely real bulk stock waiting to be packed — mark Stock unless it is not there.
A11: 5. Send it back to Tahir. Once the new build is live, each row is entered in O2S with "Packing finished" on the batch, in your name.
A13: Columns
A14: Leftover Kg = produced − packed − already accounted for. Days since last move = days since the last packing, else since the batch closed or opened.

Sheet Leftovers
A1: Product | B1: Batch | C1: Type | D1: Status | E1: Opened | F1: Closed | G1: Planned Kg | H1: Produced Kg | I1: Packed Kg | J1: Lab-cleared Kg | K1: Leftover Kg | L1: Leftover % of produced | M1: Last packed | N1: Days since last move | O1: Suggested | P1: Decision | Q1: Kg | R1: Loss reason | S1: Note
A2: Amino Acid | B2: AM26002 | C2: bulk | D2: open | E2: 2026-07-29 | G2: 700 | H2: 700 | I2: 73.5 | J2: 700 | K2: 626.5 | L2: 89.5 | M2: 2026-08-21 | N2: 36
A3: Boron 5% | B3: MAXB26002 | C3: bulk | D3: open | E3: 2026-09-25 | G3: 1000 | H3: 1000 | I3: 0 | J3: 1000 | K3: 1000 | L3: 100 | N3: 1
A4: Boron 5% | B4: VBO26001 | C4: bulk | D4: open | E4: 2026-07-28 | G4: 250 | H4: 250 | I4: 146 | J4: 250 | K4: 104 | L4: 41.6 | M4: 2026-08-28 | N4: 29
A5: Grain Set | B5: MAXKL26005 | C5: multi | D5: open | E5: 2026-09-24 | G5: 2036 | H5: 2036 | I5: 982 | J5: 2036 | K5: 1054 | L5: 51.8 | M5: 2026-09-26 | N5: 0
A6: Liquid Phosphrous | B6: VG26002 | C6: bulk | D6: open | E6: 2026-09-23 | G6: 1000 | H6: 1000 | I6: 0 | J6: 1000 | K6: 1000 | L6: 100 | N6: 3
A7: Nitro Sulfur | B7: NS26004 | C7: bulk | D7: open | E7: 2026-07-29 | G7: 4000 | H7: 4000 | I7: 3125 | J7: 4000 | K7: 875 | L7: 21.9 | M7: 2026-07-29 | N7: 59
A8: NP 6.32 | B8: GP26007 | C8: bulk | D8: open | E8: 2026-09-12 | G8: 12000 | H8: 12000 | I8: 9240 | J8: 12000 | K8: 2760 | L8: 23 | M8: 2026-09-21 | N8: 5
A9: NP 6.32 | B9: GP26008 | C9: bulk | D9: open | E9: 2026-09-14 | G9: 25000 | H9: 25000 | I9: 10710 | J9: 25000 | K9: 14290 | L9: 57.2 | M9: 2026-09-26 | N9: 0
A10: NPK 8.8.6 | B10: VLNPK26002 | C10: bulk | D10: open | E10: 2026-07-28 | G10: 500 | H10: 500 | I10: 372 | J10: 500 | K10: 128 | L10: 25.6 | M10: 2026-09-26 | N10: 0
A11: Potassium Humate | B11: HG26024 | C11: bulk | D11: open | E11: 2026-07-28 | G11: 50000 | H11: 50000 | I11: 49340 | J11: 50000 | K11: 660 | L11: 1.3 | M11: 2026-08-28 | N11: 29
A12: Potassium Humate | B12: HG26025 | C12: bulk | D12: closed | E12: 2026-08-07 | F12: 2026-08-25 | G12: 50000 | H12: 38800 | I12: 19696 | J12: 38800 | K12: 19104 | L12: 49.2 | M12: 2026-08-29 | N12: 28
A13: Potassium Humate | B13: HG26026 | C13: bulk | D13: open | E13: 2026-08-21 | G13: 50000 | H13: 50000 | I13: 49000 | J13: 50000 | K13: 1000 | L13: 2 | M13: 2026-09-11 | N13: 15
A14: Potassium Humate | B14: HG26027 | C14: bulk | D14: closed | E14: 2026-08-21 | F14: 2026-09-07 | G14: 25000 | H14: 24700 | I14: 23999 | J14: 24700 | K14: 701 | L14: 2.8 | M14: 2026-09-01 | N14: 25
A15: Potassium Humate | B15: HG26029 | C15: bulk | D15: closed | E15: 2026-08-31 | F15: 2026-09-11 | G15: 25000 | H15: 25000 | I15: 24393 | J15: 25000 | K15: 607 | L15: 2.4 | M15: 2026-09-11 | N15: 15
A16: Potassium Humate | B16: HG26030 | C16: bulk | D16: open | E16: 2026-09-07 | G16: 33000 | H16: 33000 | I16: 31984 | J16: 33000 | K16: 1016 | L16: 3.1 | M16: 2026-09-21 | N16: 5
A17: Potassium Humate | B17: HG26031 | C17: bulk | D17: open | E17: 2026-09-08 | G17: 40000 | H17: 40000 | I17: 26008 | J17: 40000 | K17: 13992 | L17: 35 | M17: 2026-09-23 | N17: 3
A18: Potassium Humate | B18: HG26032 | C18: bulk | D18: open | E18: 2026-09-12 | G18: 30000 | H18: 30000 | I18: 28544 | J18: 30000 | K18: 1456 | L18: 4.9 | M18: 2026-09-25 | N18: 1
A19: Potassium Humate | B19: HG26033 | C19: bulk | D19: open | E19: 2026-09-15 | G19: 20000 | H19: 20000 | I19: 0 | J19: 20000 | K19: 20000 | L19: 100 | N19: 11
A20: Potassium Humate | B20: HG26034 | C20: bulk | D20: open | E20: 2026-09-16 | G20: 10000 | H20: 10000 | I20: 0 | J20: 10000 | K20: 10000 | L20: 100 | N20: 10
A21: Potassium Humate | B21: HG26035 | C21: bulk | D21: open | E21: 2026-09-19 | G21: 20000 | H21: 20000 | I21: 0 | J21: 20000 | K21: 20000 | L21: 100 | N21: 7
A22: Potassium Humate | B22: HG26036 | C22: bulk | D22: open | E22: 2026-09-25 | G22: 40000 | H22: 13000 | I22: 0 | J22: 0 | K22: 13000 | L22: 100 | N22: 1
A23: Potassium Humate Liquid | B23: RUHAL26006 | C23: bulk | D23: open | E23: 2026-09-24 | G23: 10000 | H23: 10000 | I23: 4600 | J23: 10000 | K23: 5400 | L23: 54 | M23: 2026-09-25 | N23: 1
A24: Potassium Humate Liquid | B24: VB26004 | C24: bulk | D24: closed | E24: 2026-07-28 | F24: 2026-08-25 | G24: 5000 | H24: 5000 | I24: 2000 | J24: 5000 | K24: 3000 | L24: 60 | M24: 2026-08-25 | N24: 32
A25: Sulfur 70% | B25: GS10299 | C25: bulk | D25: open | E25: 2026-07-29 | G25: 900 | H25: 900 | I25: 624 | J25: 900 | K25: 276 | L25: 30.7 | M25: 2026-07-31 | N25: 57
A26: Sulfur Coated Urea | B26: VU26163 | C26: bulk | D26: open | E26: 2026-07-28 | G26: 7000 | H26: 7000 | I26: 6550 | J26: 7000 | K26: 450 | L26: 6.4 | M26: 2026-07-29 | N26: 59 | O26: By-product to Nitro Sulfur
A27: Sulfur Coated Urea | B27: VU26164 | C27: bulk | D27: open | E27: 2026-07-28 | G27: 7000 | H27: 7000 | I27: 6650 | J27: 7000 | K27: 350 | L27: 5 | M27: 2026-07-29 | N27: 59 | O27: By-product to Nitro Sulfur
A28: Sulfur Coated Urea | B28: VU26165 | C28: bulk | D28: open | E28: 2026-07-28 | G28: 7000 | H28: 7000 | I28: 6625 | J28: 7000 | K28: 375 | L28: 5.4 | M28: 2026-07-29 | N28: 59 | O28: By-product to Nitro Sulfur
A29: Sulfur Coated Urea | B29: VU26166 | C29: bulk | D29: closed | E29: 2026-07-28 | F29: 2026-08-26 | G29: 7000 | H29: 7000 | I29: 6550 | J29: 7000 | K29: 450 | L29: 6.4 | M29: 2026-07-29 | N29: 59 | O29: By-product to Nitro Sulfur
A30: Sulfur Coated Urea | B30: VU26167 | C30: bulk | D30: open | E30: 2026-07-28 | G30: 7000 | H30: 7000 | I30: 6750 | J30: 7000 | K30: 250 | L30: 3.6 | M30: 2026-07-29 | N30: 59 | O30: By-product to Nitro Sulfur
A31: Sulfur Coated Urea | B31: VU26168 | C31: bulk | D31: open | E31: 2026-07-28 | G31: 7000 | H31: 7000 | I31: 6875 | J31: 7000 | K31: 125 | L31: 1.8 | M31: 2026-07-29 | N31: 59 | O31: By-product to Nitro Sulfur
A32: Sulfur Coated Urea | B32: VU26169 | C32: bulk | D32: open | E32: 2026-07-28 | G32: 7000 | H32: 7000 | I32: 6850 | J32: 7000 | K32: 150 | L32: 2.1 | M32: 2026-07-29 | N32: 59 | O32: By-product to Nitro Sulfur
A33: Sulfur Coated Urea | B33: VU26170 | C33: bulk | D33: open | E33: 2026-07-28 | G33: 7000 | H33: 7000 | I33: 6600 | J33: 7000 | K33: 400 | L33: 5.7 | M33: 2026-07-29 | N33: 59 | O33: By-product to Nitro Sulfur
A34: Sulfur Coated Urea | B34: VU26171 | C34: bulk | D34: open | E34: 2026-07-28 | G34: 7000 | H34: 7000 | I34: 6575 | J34: 7000 | K34: 425 | L34: 6.1 | M34: 2026-07-29 | N34: 59 | O34: By-product to Nitro Sulfur
A35: Sulfur Coated Urea | B35: VU26172 | C35: bulk | D35: open | E35: 2026-07-28 | G35: 7000 | H35: 7000 | I35: 6675 | J35: 7000 | K35: 325 | L35: 4.6 | M35: 2026-07-29 | N35: 59 | O35: By-product to Nitro Sulfur
A36: Sulfur Coated Urea | B36: VU26173 | C36: bulk | D36: open | E36: 2026-07-28 | G36: 7000 | H36: 7000 | I36: 6450 | J36: 7000 | K36: 550 | L36: 7.9 | M36: 2026-07-29 | N36: 59 | O36: By-product to Nitro Sulfur
A37: Sulfur Coated Urea | B37: VU26174 | C37: bulk | D37: open | E37: 2026-07-28 | G37: 7000 | H37: 7000 | I37: 6475 | J37: 7000 | K37: 525 | L37: 7.5 | M37: 2026-07-29 | N37: 59 | O37: By-product to Nitro Sulfur
A38: Sulfur Coated Urea | B38: VU26175 | C38: bulk | D38: open | E38: 2026-07-28 | G38: 7000 | H38: 7000 | I38: 6625 | J38: 7000 | K38: 375 | L38: 5.4 | M38: 2026-07-29 | N38: 59 | O38: By-product to Nitro Sulfur
A39: Sulfur Coated Urea | B39: VU26176 | C39: bulk | D39: open | E39: 2026-07-28 | G39: 7000 | H39: 7000 | I39: 6800 | J39: 7000 | K39: 200 | L39: 2.9 | M39: 2026-07-29 | N39: 59 | O39: By-product to Nitro Sulfur
A40: Sulfur Coated Urea | B40: VU26177 | C40: bulk | D40: open | E40: 2026-07-28 | G40: 7000 | H40: 7000 | I40: 6850 | J40: 7000 | K40: 150 | L40: 2.1 | M40: 2026-07-29 | N40: 59 | O40: By-product to Nitro Sulfur
...

Sheet By product
A1: Product | B1: Batches | C1: Closed | D1: Leftover Kg
A2: Amino Acid | B2: =COUNTIF(Leftovers!A$2:A$58,A2) | C2: =COUNTIFS(Leftovers!A$2:A$58,A2,Leftovers!D$2:D$58,"closed") | D2: =SUMIF(Leftovers!A$2:A$58,A2,Leftovers!K$2:K$58)
A3: Boron 5% | B3: =COUNTIF(Leftovers!A$2:A$58,A3) | C3: =COUNTIFS(Leftovers!A$2:A$58,A3,Leftovers!D$2:D$58,"closed") | D3: =SUMIF(Leftovers!A$2:A$58,A3,Leftovers!K$2:K$58)
A4: Grain Set | B4: =COUNTIF(Leftovers!A$2:A$58,A4) | C4: =COUNTIFS(Leftovers!A$2:A$58,A4,Leftovers!D$2:D$58,"closed") | D4: =SUMIF(Leftovers!A$2:A$58,A4,Leftovers!K$2:K$58)
A5: Liquid Phosphrous | B5: =COUNTIF(Leftovers!A$2:A$58,A5) | C5: =COUNTIFS(Leftovers!A$2:A$58,A5,Leftovers!D$2:D$58,"closed") | D5: =SUMIF(Leftovers!A$2:A$58,A5,Leftovers!K$2:K$58)
A6: NP 6.32 | B6: =COUNTIF(Leftovers!A$2:A$58,A6) | C6: =COUNTIFS(Leftovers!A$2:A$58,A6,Leftovers!D$2:D$58,"closed") | D6: =SUMIF(Leftovers!A$2:A$58,A6,Leftovers!K$2:K$58)
A7: NPK 8.8.6 | B7: =COUNTIF(Leftovers!A$2:A$58,A7) | C7: =COUNTIFS(Leftovers!A$2:A$58,A7,Leftovers!D$2:D$58,"closed") | D7: =SUMIF(Leftovers!A$2:A$58,A7,Leftovers!K$2:K$58)
A8: Nitro Sulfur | B8: =COUNTIF(Leftovers!A$2:A$58,A8) | C8: =COUNTIFS(Leftovers!A$2:A$58,A8,Leftovers!D$2:D$58,"closed") | D8: =SUMIF(Leftovers!A$2:A$58,A8,Leftovers!K$2:K$58)
A9: Potassium Humate | B9: =COUNTIF(Leftovers!A$2:A$58,A9) | C9: =COUNTIFS(Leftovers!A$2:A$58,A9,Leftovers!D$2:D$58,"closed") | D9: =SUMIF(Leftovers!A$2:A$58,A9,Leftovers!K$2:K$58)
A10: Potassium Humate Liquid | B10: =COUNTIF(Leftovers!A$2:A$58,A10) | C10: =COUNTIFS(Leftovers!A$2:A$58,A10,Leftovers!D$2:D$58,"closed") | D10: =SUMIF(Leftovers!A$2:A$58,A10,Leftovers!K$2:K$58)
A11: Sulfur 70% | B11: =COUNTIF(Leftovers!A$2:A$58,A11) | C11: =COUNTIFS(Leftovers!A$2:A$58,A11,Leftovers!D$2:D$58,"closed") | D11: =SUMIF(Leftovers!A$2:A$58,A11,Leftovers!K$2:K$58)
A12: Sulfur Coated Urea | B12: =COUNTIF(Leftovers!A$2:A$58,A12) | C12: =COUNTIFS(Leftovers!A$2:A$58,A12,Leftovers!D$2:D$58,"closed") | D12: =SUMIF(Leftovers!A$2:A$58,A12,Leftovers!K$2:K$58)
A13: VL-Micro Mix | B13: =COUNTIF(Leftovers!A$2:A$58,A13) | C13: =COUNTIFS(Leftovers!A$2:A$58,A13,Leftovers!D$2:D$58,"closed") | D13: =SUMIF(Leftovers!A$2:A$58,A13,Leftovers!K$2:K$58)
... A16: Zinc 21% | B16: =COUNTIF(Leftovers!A$2:A$58,A16) | C16: =COUNTIFS(Leftovers!A$2:A$58,A16,Leftovers!D$2:D$58,"closed") | D16: =SUMIF(Leftovers!A$2:A$58,A16,Leftovers!K$2:K$58)
A17: Total | B17: =SUM(B2:B16) | C17: =SUM(C2:C16) | D17: =SUM(D2:D16)
